Workbook

Sheet 商品销售
A1: 商品销售统计表
A2: 商品编号 | B2: 商品名 | C2: 商品类别 | D2: 月份 | E2: 单价 | F2: 数量 | G2: 销售金额
A3: 001 | B3: 高压锅 | C3: 日用品 | D3: 1 | E3: 68 | F3: 20 | G3: =F3*E3 -> 1360
A4: 002 | B4: 冰箱 | C4: 电器 | D4: 1 | E4: 2780 | F4: 30 | G4: =F4*E4 -> 83400
A5: 003 | B5: 音响 | C5: 电器 | D5: 1 | E5: 4200 | F5: 15 | G5: =F5*E5 -> 63000
A6: 004 | B6: 女大衣 | C6: 服装 | D6: 1 | E6: 457 | F6: 60 | G6: =F6*E6 -> 27420
A7: 005 | B7: 彩电 | C7: 电器 | D7: 1 | E7: 3800 | F7: 50 | G7: =F7*E7 -> 190000
A8: 006 | B8: 热水瓶 | C8: 日用品 | D8: 1 | E8: 32 | F8: 40 | G8: =F8*E8 -> 1280
A9: 007 | B9: 西装 | C9: 服装 | D9: 1 | E9: 382 | F9: 85 | G9: =F9*E9 -> 32470
A10: 008 | B10: 护肤霜 | C10: 化妆品 | D10: 1 | E10: 80 | F10: 12 | G10: =F10*E10 -> 960
A11: 009 | B11: 空调 | C11: 电器 | D11: 1 | E11: 2800 | F11: 60 | G11: =F11*E11 -> 168000
A12: 010 | B12: 洗发水 | C12: 化妆品 | D12: 1 | E12: 65 | F12: 45 | G12: =F12*E12 -> 2925
A13: 011 | B13: 高压锅 | C13: 日用品 | D13: 2 | E13: 68 | F13: 5 | G13: =F13*E13 -> 340
A14: 012 | B14: 冰箱 | C14: 电器 | D14: 2 | E14: 2780 | F14: 25 | G14: =F14*E14 -> 69500
... A32: 030 | B32: 洗发水 | C32: 化妆品 | D32: 3 | E32: 65 | F32: 32 | G32: =F32*E32 -> 2080

Sheet 销售汇总
A1: 商品编号 | B1: 商品名 | C1: 一月份销售金额 | D1: 二月份销售金额 | E1: 三月份销售金额
A2: 001 | B2: 高压锅 | C2: =SUMIF(商品销售!$B$3:$B$12,B2,商品销售!$G$3:$G$12) -> 1360 | D2: =SUMIF(商品销售!$B$13:$B$22,B2,商品销售!$G$13:$G$22) -> 340 | E2: =SUMIF(商品销售!$B$23:$B$32,B2,商品销售!$G$23:$G$32) -> 680
A3: 002 | B3: 冰箱 | C3: =SUMIF(商品销售!$B$3:$B$12,B3,商品销售!$G$3:$G$12) -> 83400 | D3: =SUMIF(商品销售!$B$13:$B$22,B3,商品销售!$G$13:$G$22) -> 69500 | E3: =SUMIF(商品销售!$B$23:$B$32,B3,商品销售!$G$23:$G$32) -> 83400
A4: 003 | B4: 音响 | C4: =SUMIF(商品销售!$B$3:$B$12,B4,商品销售!$G$3:$G$12) -> 63000 | D4: =SUMIF(商品销售!$B$13:$B$22,B4,商品销售!$G$13:$G$22) -> 84000 | E4: =SUMIF(商品销售!$B$23:$B$32,B4,商品销售!$G$23:$G$32) -> 63000
A5: 004 | B5: 女大衣 | C5: =SUMIF(商品销售!$B$3:$B$12,B5,商品销售!$G$3:$G$12) -> 27420 | D5: =SUMIF(商品销售!$B$13:$B$22,B5,商品销售!$G$13:$G$22) -> 20565 | E5: =SUMIF(商品销售!$B$23:$B$32,B5,商品销售!$G$23:$G$32) -> 31076
A6: 005 | B6: 彩电 | C6: =SUMIF(商品销售!$B$3:$B$12,B6,商品销售!$G$3:$G$12) -> 190000 | D6: =SUMIF(商品销售!$B$13:$B$22,B6,商品销售!$G$13:$G$22) -> 140600 | E6: =SUMIF(商品销售!$B$23:$B$32,B6,商品销售!$G$23:$G$32) -> 171000
A7: 006 | B7: 热水瓶 | C7: =SUMIF(商品销售!$B$3:$B$12,B7,商品销售!$G$3:$G$12) -> 1280 | D7: =SUMIF(商品销售!$B$13:$B$22,B7,商品销售!$G$13:$G$22) -> 320 | E7: =SUMIF(商品销售!$B$23:$B$32,B7,商品销售!$G$23:$G$32) -> 832
A8: 007 | B8: 西装 | C8: =SUMIF(商品销售!$B$3:$B$12,B8,商品销售!$G$3:$G$12) -> 32470 | D8: =SUMIF(商品销售!$B$13:$B$22,B8,商品销售!$G$13:$G$22) -> 38200 | E8: =SUMIF(商品销售!$B$23:$B$32,B8,商品销售!$G$23:$G$32) -> 19100
A9: 008 | B9: 护肤霜 | C9: =SUMIF(商品销售!$B$3:$B$12,B9,商品销售!$G$3:$G$12) -> 960 | D9: =SUMIF(商品销售!$B$13:$B$22,B9,商品销售!$G$13:$G$22) -> 800 | E9: =SUMIF(商品销售!$B$23:$B$32,B9,商品销售!$G$23:$G$32) -> 1280
A10: 009 | B10: 空调 | C10: =SUMIF(商品销售!$B$3:$B$12,B10,商品销售!$G$3:$G$12) -> 168000 | D10: =SUMIF(商品销售!$B$13:$B$22,B10,商品销售!$G$13:$G$22) -> 168000 | E10: =SUMIF(商品销售!$B$23:$B$32,B10,商品销售!$G$23:$G$32) -> 72800
A11: 010 | B11: 洗发水 | C11: =SUMIF(商品销售!$B$3:$B$12,B11,商品销售!$G$3:$G$12) -> 2925 | D11: =SUMIF(商品销售!$B$13:$B$22,B11,商品销售!$G$13:$G$22) -> 2925 | E11: =SUMIF(商品销售!$B$23:$B$32,B11,商品销售!$G$23:$G$32) -> 2080

Sheet 商品月份汇总
A2: 商品编号 | B2: 商品名 | C2: 商品类别 | D2: 月份 | E2: 单价 | F2: 数量 | G2: 销售金额
A3: 002 | B3: 冰箱 | C3: 电器 | D3: 1 | E3: 2780 | F3: 30 | G3: 83400
A4: 012 | B4: 冰箱 | C4: 电器 | D4: 2 | E4: 2780 | F4: 25 | G4: 69500
A5: 022 | B5: 冰箱 | C5: 电器 | D5: 3 | E5: 2780 | F5: 30 | G5: 83400
B6: 冰箱 汇总 | G6: =SUBTOTAL(9,G3:G5) -> 236300
A7: 005 | B7: 彩电 | C7: 电器 | D7: 1 | E7: 3800 | F7: 50 | G7: 190000
A8: 015 | B8: 彩电 | C8: 电器 | D8: 2 | E8: 3800 | F8: 37 | G8: 140600
A9: 025 | B9: 彩电 | C9: 电器 | D9: 3 | E9: 3800 | F9: 45 | G9: 171000
B10: 彩电 汇总 | G10: =SUBTOTAL(9,G7:G9) -> 501600
A11: 001 | B11: 高压锅 | C11: 日用品 | D11: 1 | E11: 68 | F11: 20 | G11: 1360
A12: 011 | B12: 高压锅 | C12: 日用品 | D12: 2 | E12: 68 | F12: 5 | G12: 340
A13: 021 | B13: 高压锅 | C13: 日用品 | D13: 3 | E13: 68 | F13: 10 | G13: 680
B14: 高压锅 汇总 | G14: =SUBTOTAL(9,G11:G13) -> 2380
A15: 008 | B15: 护肤霜 | C15: 化妆品 | D15: 1 | E15: 80 | F15: 12 | G15: 960
A16: 018 | B16: 护肤霜 | C16: 化妆品 | D16: 2 | E16: 80 | F16: 10 | G16: 800
A17: 028 | B17: 护肤霜 | C17: 化妆品 | D17: 3 | E17: 80 | F17: 16 | G17: 1280
B18: 护肤霜 汇总 | G18: =SUBTOTAL(9,G15:G17) -> 3040
A19: 009 | B19: 空调 | C19: 电器 | D19: 1 | E19: 2800 | F19: 60 | G19: 168000
A20: 019 | B20: 空调 | C20: 电器 | D20: 2 | E20: 2800 | F20: 60 | G20: 168000
A21: 029 | B21: 空调 | C21: 电器 | D21: 3 | E21: 2800 | F21: 26 | G21: 72800
B22: 空调 汇总 | G22: =SUBTOTAL(9,G19:G21) -> 408800
A23: 004 | B23: 女大衣 | C23: 服装 | D23: 1 | E23: 457 | F23: 60 | G23: 27420
A24: 014 | B24: 女大衣 | C24: 服装 | D24: 2 | E24: 457 | F24: 45 | G24: 20565
A25: 024 | B25: 女大衣 | C25: 服装 | D25: 3 | E25: 457 | F25: 68 | G25: 31076
B26: 女大衣 汇总 | G26: =SUBTOTAL(9,G23:G25) -> 79061
A27: 006 | B27: 热水瓶 | C27: 日用品 | D27: 1 | E27: 32 | F27: 40 | G27: 1280
A28: 016 | B28: 热水瓶 | C28: 日用品 | D28: 2 | E28: 32 | F28: 10 | G28: 320
A29: 026 | B29: 热水瓶 | C29: 日用品 | D29: 3 | E29: 32 | F29: 26 | G29: 832
B30: 热水瓶 汇总 | G30: =SUBTOTAL(9,G27:G29) -> 2432
A31: 007 | B31: 西装 | C31: 服装 | D31: 1 | E31: 382 | F31: 85 | G31: 32470
A32: 017 | B32: 西装 | C32: 服装 | D32: 2 | E32: 382 | F32: 100 | G32: 38200
A33: 027 | B33: 西装 | C33: 服装 | D33: 3 | E33: 382 | F33: 50 | G33: 19100
B34: 西装 汇总 | G34: =SUBTOTAL(9,G31:G33) -> 89770
A35: 010 | B35: 洗发水 | C35: 化妆品 | D35: 1 | E35: 65 | F35: 45 | G35: 2925
A36: 020 | B36: 洗发水 | C36: 化妆品 | D36: 2 | E36: 65 | F36: 45 | G36: 2925
A37: 030 | B37: 洗发水 | C37: 化妆品 | D37: 3 | E37: 65 | F37: 32 | G37: 2080
B38: 洗发水 汇总 | G38: =SUBTOTAL(9,G35:G37) -> 7930
A39: 003 | B39: 音响 | C39: 电器 | D39: 1 | E39: 4200 | F39: 15 | G39: 63000
A40: 013 | B40: 音响 | C40: 电器 | D40: 2 | E40: 4200 | F40: 20 | G40: 84000
A41: 023 | B41: 音响 | C41: 电器 | D41: 3 | E41: 4200 | F41: 15 | G41: 63000
...
