Workbook

Sheet Sheet1
A1: 计算机成绩表
A2: 编号 | B2: 学号 | C2: 姓名 | D2: 性别 | E2: 出生日期 | F2: 籍贯 | G2: 院系 | H2: C语言 | I2: Word | J2: Excel | K2: PPT | L2: Access | M2: 成绩
A3: 0001 | B3: 090010144 | C3: 褚梦佳 | D3: 女 | E3: 33288 | F3: 山东 | G3: 文学院 | H3: 14 | I3: 15 | J3: 10 | K3: 6 | L3: 9 | M3: =IF(COUNTIF(H3:L3,"=0")>=2,0,SUM(H3:L3)) -> 54
A4: 0002 | B4: 090010145 | C4: 蔡敏梅 | D4: 女 | E4: 33280 | F4: 上海 | G4: 文学院 | H4: 11 | I4: 19 | J4: 19 | K4: 10 | L4: 9 | M4: =IF(COUNTIF(H4:L4,"=0")>=2,0,SUM(H4:L4)) -> 68
A5: 0003 | B5: 090010146 | C5: 赵林莉 | D5: 女 | E5: 33574 | F5: 江苏 | G5: 文学院 | H5: 35 | I5: 20 | J5: 17 | K5: 7 | L5: 9 | M5: =IF(COUNTIF(H5:L5,"=0")>=2,0,SUM(H5:L5)) -> 88
A6: 0004 | B6: 090010147 | C6: 糜义杰 | D6: 男 | E6: 33514 | F6: 江苏 | G6: 文学院 | H6: 29 | I6: 19 | J6: 19 | K6: 10 | L6: 9 | M6: =IF(COUNTIF(H6:L6,"=0")>=2,0,SUM(H6:L6)) -> 86
A7: 0005 | B7: 090010148 | C7: 周丽萍 | D7: 女 | E7: 33314 | F7: 江苏 | G7: 文学院 | H7: 24 | I7: 18 | J7: 14 | K7: 7 | L7: 9 | M7: =IF(COUNTIF(H7:L7,"=0")>=2,0,SUM(H7:L7)) -> 72
A8: 0006 | B8: 090010149 | C8: 王英 | D8: 女 | E8: 33430 | F8: 江苏 | G8: 文学院 | H8: 20 | I8: 20 | J8: 16 | K8: 10 | L8: 9 | M8: =IF(COUNTIF(H8:L8,"=0")>=2,0,SUM(H8:L8)) -> 75
A9: 0007 | B9: 090010150 | C9: 陈子雅 | D9: 男 | E9: 33286 | F9: 江苏 | G9: 文学院 | H9: 22 | I9: 18 | J9: 16 | K9: 10 | L9: 9 | M9: =IF(COUNTIF(H9:L9,"=0")>=2,0,SUM(H9:L9)) -> 75
A10: 0008 | B10: 090010151 | C10: 周文洁 | D10: 女 | E10: 33317 | F10: 上海 | G10: 文学院 | H10: 28 | I10: 20 | J10: 12 | K10: 10 | L10: 9 | M10: =IF(COUNTIF(H10:L10,"=0")>=2,0,SUM(H10:L10)) -> 79
A11: 0009 | B11: 090010152 | C11: 成立 | D11: 男 | E11: 33287 | F11: 江苏 | G11: 文学院 | H11: 26 | I11: 18 | J11: 18 | K11: 10 | L11: 9 | M11: =IF(COUNTIF(H11:L11,"=0")>=2,0,SUM(H11:L11)) -> 81
A12: 0010 | B12: 090010153 | C12: 陈晖 | D12: 男 | E12: 33283 | F12: 江苏 | G12: 文学院 | H12: 26 | I12: 20 | J12: 16 | K12: 9 | L12: 9 | M12: =IF(COUNTIF(H12:L12,"=0")>=2,0,SUM(H12:L12)) -> 80
A13: 0011 | B13: 090010154 | C13: 王玉芳 | D13: 女 | E13: 33431 | F13: 江苏 | G13: 文学院 | H13: 33 | I13: 20 | J13: 19 | K13: 10 | L13: 9 | M13: =IF(COUNTIF(H13:L13,"=0")>=2,0,SUM(H13:L13)) -> 91
A14: 0012 | B14: 090010155 | C14: 邵艳 | D14: 女 | E14: 33251 | F14: 江苏 | G14: 文学院 | H14: 24 | I14: 20 | J14: 20 | K14: 10 | L14: 9 | M14: =IF(COUNTIF(H14:L14,"=0")>=2,0,SUM(H14:L14)) -> 83
... A396: 0394 | B396: 090100740 | C396: 康婷婷 | D396: 女 | E396: 33416 | F396: 山东 | G396: 体科院 | H396: 19 | I396: 18 | J396: 13 | K396: 6 | L396: 1 | M396: =IF(COUNTIF(H396:L396,"=0")>=2,0,SUM(H396:L396)) -> 57

Sheet Sheet2
A1: 计算机成绩表
A2: 编号 | B2: 学号 | C2: 姓名 | D2: 性别 | E2: 出生日期 | F2: 籍贯 | G2: 院系 | H2: C语言 | I2: Word | J2: Excel | K2: PPT | L2: Access | M2: 成绩
A3: 0198 | B3: 090060301 | C3: 章银兰 | D3: 女 | E3: 33570 | F3: 江苏 | G3: 地科院 | H3: 26 | I3: 19 | J3: 20 | K3: 10 | L3: 10 | M3: 85
A4: 0199 | B4: 090060302 | C4: 周洪彬 | D4: 男 | E4: 33308 | F4: 江苏 | G4: 地科院 | H4: 31 | I4: 13 | J4: 16 | K4: 10 | L4: 9 | M4: 79
A5: 0200 | B5: 090060303 | C5: 姜立英 | D5: 女 | E5: 33406 | F5: 北京 | G5: 地科院 | H5: 35 | I5: 15 | J5: 17 | K5: 10 | L5: 7 | M5: 84
A6: 0201 | B6: 090060304 | C6: 赵锐 | D6: 男 | E6: 33575 | F6: 江苏 | G6: 地科院 | H6: 28 | I6: 20 | J6: 19 | K6: 10 | L6: 2 | M6: 79
A7: 0202 | B7: 090060305 | C7: 雷沁 | D7: 男 | E7: 33420 | F7: 江苏 | G7: 地科院 | H7: 27 | I7: 17 | J7: 17 | K7: 9 | L7: 2 | M7: 72
A8: 0203 | B8: 090060306 | C8: 王秀娟 | D8: 女 | E8: 33514 | F8: 江苏 | G8: 地科院 | H8: 35 | I8: 20 | J8: 19 | K8: 10 | L8: 3 | M8: 87
A9: 0204 | B9: 090060307 | C9: 戴方敏 | D9: 女 | E9: 33290 | F9: 江苏 | G9: 地科院 | H9: 26 | I9: 17 | J9: 14 | K9: 2 | L9: 0 | M9: 59
A10: 0205 | B10: 090060308 | C10: 黄长杰 | D10: 男 | E10: 33383 | F10: 江苏 | G10: 地科院 | H10: 34 | I10: 18 | J10: 18 | K10: 10 | L10: 8 | M10: 88
A11: 0206 | B11: 090060309 | C11: 马兰 | D11: 女 | E11: 33510 | F11: 江苏 | G11: 地科院 | H11: 37 | I11: 16 | J11: 18 | K11: 10 | L11: 10 | M11: 91
A12: 0207 | B12: 090060310 | C12: 林春艳 | D12: 女 | E12: 33480 | F12: 江苏 | G12: 地科院 | H12: 25 | I12: 17 | J12: 19 | K12: 10 | L12: 8 | M12: 79
A13: 0208 | B13: 090060311 | C13: 于清 | D13: 女 | E13: 33540 | F13: 江苏 | G13: 地科院 | H13: 27 | I13: 20 | J13: 19 | K13: 10 | L13: 9 | M13: 85
A14: 0209 | B14: 090060312 | C14: 章勇 | D14: 男 | E14: 33571 | F14: 江苏 | G14: 地科院 | H14: 35 | I14: 20 | J14: 16 | K14: 10 | L14: 8 | M14: 89
... A36: 0231 | B36: 090060334 | C36: 王志超 | D36: 男 | E36: 33512 | F36: 江苏 | G36: 地科院 | H36: 32 | I36: 11 | J36: 0 | K36: 0 | L36: 0 | M36: 0
G37: 地科院 平均值 | M37: =SUBTOTAL(1,M3:M36) -> 67.529412
A38: 0260 | B38: 090080501 | C38: 庄思瑜 | D38: 女 | E38: 33621 | F38: 江苏 | G38: 法学院 | H38: 35 | I38: 20 | J38: 18 | K38: 8 | L38: 10 | M38: 91
A39: 0261 | B39: 090080502 | C39: 黄丽美 | D39: 女 | E39: 33390 | F39: 江苏 | G39: 法学院 | H39: 31 | I39: 20 | J39: 20 | K39: 10 | L39: 10 | M39: 91
A40: 0262 | B40: 090080503 | C40: 倪晓敏 | D40: 女 | E40: 33519 | F40: 江苏 | G40: 法学院 | H40: 35 | I40: 20 | J40: 20 | K40: 10 | L40: 10 | M40: 95
A41: 0263 | B41: 090080504 | C41: 徐丽 | D41: 女 | E41: 33546 | F41: 江苏 | G41: 法学院 | H41: 24 | I41: 18 | J41: 20 | K41: 10 | L41: 10 | M41: 82
A42: 0264 | B42: 090080505 | C42: 郭帅婷 | D42: 女 | E42: 33288 | F42: 江苏 | G42: 法学院 | H42: 36 | I42: 20 | J42: 20 | K42: 10 | L42: 10 | M42: 96
A43: 0265 | B43: 090080506 | C43: 许园园 | D43: 女 | E43: 33553 | F43: 江苏 | G43: 法学院 | H43: 29 | I43: 18 | J43: 20 | K43: 10 | L43: 9 | M43: 86
A44: 0266 | B44: 090080507 | C44: 蔡爱思 | D44: 女 | E44: 33277 | F44: 北京 | G44: 法学院 | H44: 28 | I44: 19 | J44: 20 | K44: 10 | L44: 10 | M44: 87
A45: 0267 | B45: 090080508 | C45: 王华 | D45: 女 | E45: 33404 | F45: 江苏 | G45: 法学院 | H45: 38 | I45: 19 | J45: 20 | K45: 10 | L45: 10 | M45: 97
A46: 0268 | B46: 090080509 | C46: 黄鑫楼 | D46: 男 | E46: 33399 | F46: 江苏 | G46: 法学院 | H46: 14 | I46: 16 | J46: 5 | K46: 6 | L46: 0 | M46: 41
A47: 0269 | B47: 090080510 | C47: 王娜 | D47: 女 | E47: 33411 | F47: 山东 | G47: 法学院 | H47: 35 | I47: 19 | J47: 20 | K47: 10 | L47: 10 | M47: 94
A48: 0270 | B48: 090080511 | C48: 刘亮亮 | D48: 男 | E48: 33497 | F48: 江苏 | G48: 法学院 | H48: 36 | I48: 20 | J48: 19 | K48: 10 | L48: 9 | M48: 94
A49: 0271 | B49: 090080512 | C49: 秦韦 | D49: 男 | E49: 33515 | F49: 江苏 | G49: 法学院 | H49: 35 | I49: 19 | J49: 17 | K49: 10 | L49: 10 | M49: 91
... A86: 0308 | B86: 090080549 | C86: 唐杰 | D86: 男 | E86: 33394 | F86: 江苏 | G86: 法学院 | H86: 20 | I86: 17 | J86: 20 | K86: 8 | L86: 9 | M86: 74
G87: 法学院 平均值 | M87: =SUBTOTAL(1,M38:M86) -> 82.632653
A88: 0309 | B88: 090090601 | C88: 彭先锋 | D88: 男 | E88: 33513 | F88: 江苏 | G88: 公管院 | H88: 26 | I88: 20 | J88: 20 | K88: 10 | L88: 10 | M88: 86
A89: 0310 | B89: 090090602 | C89: 王丽 | D89: 女 | E89: 33407 | F89: 江苏 | G89: 公管院 | H89: 30 | I89: 20 | J89: 20 | K89: 10 | L89: 10 | M89: 90
A90: 0311 | B90: 090090603 | C90: 徐莉莉 | D90: 女 | E90: 33545 | F90: 江苏 | G90: 公管院 | H90: 17 | I90: 18 | J90: 19 | K90: 6 | L90: 9 | M90: 69
A91: 0312 | B91: 090090604 | C91: 孙友年 | D91: 男 | E91: 33280 | F91: 江苏 | G91: 公管院 | H91: 26 | I91: 19 | J91: 8 | K91: 6 | L91: 8 | M91: 67
A92: 0313 | B92: 090090605 | C92: 张国珍 | D92: 女 | E92: 33552 | F92: 江苏 | G92: 公管院 | H92: 34 | I92: 15 | J92: 17 | K92: 7 | L92: 9 | M92: 82
A93: 0314 | B93: 090090606 | C93: 张春英 | D93: 女 | E93: 33549 | F93: 江苏 | G93: 公管院 | H93: 24 | I93: 17 | J93: 20 | K93: 8 | L93: 9 | M93: 78
A94: 0315 | B94: 090090607 | C94: 睢培 | D94: 女 | E94: 33271 | F94: 江苏 | G94: 公管院 | H94: 25 | I94: 19 | J94: 19 | K94: 10 | L94: 8 | M94: 81
A95: 0316 | B95: 090090608 | C95: 钱文娟 | D95: 女 | E95: 33513 | F95: 江苏 | G95: 公管院 | H95: 32 | I95: 19 | J95: 20 | K95: 8 | L95: 9 | M95: 88
A96: 0317 | B96: 090090609 | C96: 姚仙芳 | D96: 女 | E96: 33566 | F96: 江苏 | G96: 公管院 | H96: 25 | I96: 17 | J96: 20 | K96: 8 | L96: 9 | M96: 79
A97: 0318 | B97: 090090610 | C97: 单秋玲 | D97: 女 | E97: 33345 | F97: 江苏 | G97: 公管院 | H97: 31 | I97: 18 | J97: 18 | K97: 8 | L97: 9 | M97: 84
...

Sheet Sheet3
A1: 计算机成绩表
A2: 编号 | B2: 学号 | C2: 姓名 | D2: 性别 | E2: 出生日期 | F2: 籍贯 | G2: 院系 | H2: C语言 | I2: Word | J2: Excel | K2: PPT | L2: Access | M2: 成绩 | P2: 籍贯
A3: 0001 | B3: 090010144 | C3: 褚梦佳 | D3: 女 | E3: 33288 | F3: 山东 | G3: 文学院 | H3: 14 | I3: 15 | J3: 10 | K3: 6 | L3: 9 | M3: 54 | P3: 上海 | Q3: =成绩>MEDIAN($M$3:$M$396) -> #NAME?
A4: 0002 | B4: 090010145 | C4: 蔡敏梅 | D4: 女 | E4: 33280 | F4: 上海 | G4: 文学院 | H4: 11 | I4: 19 | J4: 19 | K4: 10 | L4: 9 | M4: 68 | P4: 江苏 | Q4: =成绩>MEDIAN($M$3:$M$396) -> #NAME?
A5: 0003 | B5: 090010146 | C5: 赵林莉 | D5: 女 | E5: 33574 | F5: 江苏 | G5: 文学院 | H5: 35 | I5: 20 | J5: 17 | K5: 7 | L5: 9 | M5: 88
A6: 0004 | B6: 090010147 | C6: 糜义杰 | D6: 男 | E6: 33514 | F6: 江苏 | G6: 文学院 | H6: 29 | I6: 19 | J6: 19 | K6: 10 | L6: 9 | M6: 86
A7: 0005 | B7: 090010148 | C7: 周丽萍 | D7: 女 | E7: 33314 | F7: 江苏 | G7: 文学院 | H7: 24 | I7: 18 | J7: 14 | K7: 7 | L7: 9 | M7: 72 | P7: 编号 | Q7: 学号 | R7: 姓名 | S7: 性别 | T7: 出生日期 | U7: 籍贯 | V7: 院系 | W7: C语言 | X7: Word | Y7: Excel | Z7: PPT | AA7: Access | AB7: 成绩
A8: 0006 | B8: 090010149 | C8: 王英 | D8: 女 | E8: 33430 | F8: 江苏 | G8: 文学院 | H8: 20 | I8: 20 | J8: 16 | K8: 10 | L8: 9 | M8: 75 | P8: 0003 | Q8: 090010146 | R8: 赵林莉 | S8: 女 | T8: 33574 | U8: 江苏 | V8: 文学院 | W8: 35 | X8: 20 | Y8: 17 | Z8: 7 | AA8: 9 | AB8: 88
A9: 0007 | B9: 090010150 | C9: 陈子雅 | D9: 男 | E9: 33286 | F9: 江苏 | G9: 文学院 | H9: 22 | I9: 18 | J9: 16 | K9: 10 | L9: 9 | M9: 75 | P9: 0004 | Q9: 090010147 | R9: 糜义杰 | S9: 男 | T9: 33514 | U9: 江苏 | V9: 文学院 | W9: 29 | X9: 19 | Y9: 19 | Z9: 10 | AA9: 9 | AB9: 86
A10: 0008 | B10: 090010151 | C10: 周文洁 | D10: 女 | E10: 33317 | F10: 上海 | G10: 文学院 | H10: 28 | I10: 20 | J10: 12 | K10: 10 | L10: 9 | M10: 79 | P10: 0008 | Q10: 090010151 | R10: 周文洁 | S10: 女 | T10: 33317 | U10: 上海 | V10: 文学院 | W10: 28 | X10: 20 | Y10: 12 | Z10: 10 | AA10: 9 | AB10: 79
A11: 0009 | B11: 090010152 | C11: 成立 | D11: 男 | E11: 33287 | F11: 江苏 | G11: 文学院 | H11: 26 | I11: 18 | J11: 18 | K11: 10 | L11: 9 | M11: 81 | P11: 0009 | Q11: 090010152 | R11: 成立 | S11: 男 | T11: 33287 | U11: 江苏 | V11: 文学院 | W11: 26 | X11: 18 | Y11: 18 | Z11: 10 | AA11: 9 | AB11: 81
A12: 0010 | B12: 090010153 | C12: 陈晖 | D12: 男 | E12: 33283 | F12: 江苏 | G12: 文学院 | H12: 26 | I12: 20 | J12: 16 | K12: 9 | L12: 9 | M12: 80 | P12: 0010 | Q12: 090010153 | R12: 陈晖 | S12: 男 | T12: 33283 | U12: 江苏 | V12: 文学院 | W12: 26 | X12: 20 | Y12: 16 | Z12: 9 | AA12: 9 | AB12: 80
A13: 0011 | B13: 090010154 | C13: 王玉芳 | D13: 女 | E13: 33431 | F13: 江苏 | G13: 文学院 | H13: 33 | I13: 20 | J13: 19 | K13: 10 | L13: 9 | M13: 91 | P13: 0011 | Q13: 090010154 | R13: 王玉芳 | S13: 女 | T13: 33431 | U13: 江苏 | V13: 文学院 | W13: 33 | X13: 20 | Y13: 19 | Z13: 10 | AA13: 9 | AB13: 91
A14: 0012 | B14: 090010155 | C14: 邵艳 | D14: 女 | E14: 33251 | F14: 江苏 | G14: 文学院 | H14: 24 | I14: 20 | J14: 20 | K14: 10 | L14: 9 | M14: 83 | P14: 0012 | Q14: 090010155 | R14: 邵艳 | S14: 女 | T14: 33251 | U14: 江苏 | V14: 文学院 | W14: 24 | X14: 20 | Y14: 20 | Z14: 10 | AA14: 9 | AB14: 83
A15: 0013 | B15: 090010156 | C15: 殷岳峰 | D15: 男 | E15: 33570 | F15: 山东 | G15: 文学院 | H15: 15 | I15: 15 | J15: 19 | K15: 7 | L15: 9 | M15: 65 | P15: 0015 | Q15: 090010102 | R15: 王海霞 | S15: 女 | T15: 33402 | U15: 江苏 | V15: 文学院 | W15: 32 | X15: 20 | Y15: 18 | Z15: 10 | AA15: 10 | AB15: 90
A16: 0014 | B16: 090010101 | C16: 董红 | D16: 女 | E16: 33349 | F16: 江苏 | G16: 文学院 | H16: 31 | I16: 9 | J16: 0 | K16: 4 | L16: 8 | M16: 52 | P16: 0016 | Q16: 090010103 | R16: 闫静 | S16: 女 | T16: 33557 | U16: 江苏 | V16: 文学院 | W16: 33 | X16: 18 | Y16: 10 | Z16: 10 | AA16: 10 | AB16: 81
A17: 0015 | B17: 090010102 | C17: 王海霞 | D17: 女 | E17: 33402 | F17: 江苏 | G17: 文学院 | H17: 32 | I17: 20 | J17: 18 | K17: 10 | L17: 10 | M17: 90 | P17: 0017 | Q17: 090010104 | R17: 裴娟娟 | S17: 女 | T17: 33524 | U17: 江苏 | V17: 文学院 | W17: 31 | X17: 18 | Y17: 19 | Z17: 10 | AA17: 7 | AB17: 85
A18: 0016 | B18: 090010103 | C18: 闫静 | D18: 女 | E18: 33557 | F18: 江苏 | G18: 文学院 | H18: 33 | I18: 18 | J18: 10 | K18: 10 | L18: 10 | M18: 81 | P18: 0018 | Q18: 090010105 | R18: 曹淤青 | S18: 男 | T18: 33286 | U18: 江苏 | V18: 文学院 | W18: 27 | X18: 18 | Y18: 20 | Z18: 10 | AA18: 9 | AB18: 84
A19: 0017 | B19: 090010104 | C19: 裴娟娟 | D19: 女 | E19: 33524 | F19: 江苏 | G19: 文学院 | H19: 31 | I19: 18 | J19: 19 | K19: 10 | L19: 7 | M19: 85 | P19: 0021 | Q19: 090010108 | R19: 谢洁 | S19: 女 | T19: 33528 | U19: 江苏 | V19: 文学院 | W19: 30 | X19: 18 | Y19: 20 | Z19: 10 | AA19: 9 | AB19: 87
... A172: 0170 | B172: 090050227 | C172: 张春丽 | D172: 女 | E172: 33548 | F172: 河南 | G172: 生科院 | H172: 35 | I172: 20 | J172: 18 | K172: 10 | L172: 9 | M172: 92 | P172: 0392 | Q172: 090100738 | R172: 黄玲玲 | S172: 女 | T172: 33392 | U172: 江苏 | V172: 体科院 | W172: 28 | X172: 17 | Y172: 20 | Z172: 6 | AA172: 9 | AB172: 80
A173: 0171 | B173: 090050228 | C173: 杨云 | D173: 女 | E173: 33565 | F173: 江苏 | G173: 生科院 | H173: 35 | I173: 19 | J173: 17 | K173: 10 | L173: 9 | M173: 90
A174: 0172 | B174: 090050229 | C174: 曾彩虹 | D174: 女 | E174: 33543 | F174: 江苏 | G174: 生科院 | H174: 27 | I174: 19 | J174: 17 | K174: 10 | L174: 9 | M174: 82
A175: 0173 | B175: 090050230 | C175: 刘芳 | D175: 女 | E175: 33493 | F175: 北京 | G175: 生科院 | H175: 35 | I175: 17 | J175: 18 | K175: 10 | L175: 9 | M175: 89
A176: 0174 | B176: 090050231 | C176: 许美玲 | D176: 女 | E176: 33552 | F176: 江苏 | G176: 生科院 | H176: 30 | I176: 20 | J176: 19 | K176: 10 | L176: 8 | M176: 87
A177: 0175 | B177: 090050232 | C177: 孟新翔 | D177: 男 | E177: 33513 | F177: 江苏 | G177: 生科院 | H177: 32 | I177: 20 | J177: 19 | K177: 10 | L177: 9 | M177: 90
A178: 0176 | B178: 090050233 | C178: 韩玉鑫 | D178: 女 | E178: 33289 | F178: 山东 | G178: 生科院 | H178: 22 | I178: 20 | J178: 19 | K178: 10 | L178: 9 | M178: 80
A179: 0177 | B179: 090050234 | C179: 祁欣 | D179: 男 | E179: 33517 | F179: 江苏 | G179: 生科院 | H179: 33 | I179: 18 | J179: 20 | K179: 8 | L179: 9 | M179: 88
A180: 0178 | B180: 090050235 | C180: 李玉祥 | D180: 男 | E180: 33437 | F180: 江苏 | G180: 生科院 | H180: 31 | I180: 20 | J180: 16 | K180: 10 | L180: 10 | M180: 87
A181: 0179 | B181: 090050236 | C181: 曹光雪 | D181: 男 | E181: 33282 | F181: 江苏 | G181: 生科院 | H181: 37 | I181: 19 | J181: 19 | K181: 10 | L181: 9 | M181: 94
A182: 0180 | B182: 090050237 | C182: 张柯 | D182: 女 | E182: 33557 | F182: 江苏 | G182: 生科院 | H182: 34 | I182: 19 | J182: 20 | K182: 10 | L182: 9 | M182: 92
A183: 0181 | B183: 090050238 | C183: 王桥 | D183: 女 | E183: 33513 | F183: 江苏 | G183: 生科院 | H183: 36 | I183: 18 | J183: 19 | K183: 10 | L183: 9 | M183: 92
A184: 0182 | B184: 090050239 | C184: 魏冉 | D184: 女 | E184: 33515 | F184: 江苏 | G184: 生科院 | H184: 31 | I184: 19 | J184: 18 | K184: 9 | L184: 9 | M184: 86
... A396: 0394 | B396: 090100740 | C396: 康婷婷 | D396: 女 | E396: 33416 | F396: 山东 | G396: 体科院 | H396: 19 | I396: 18 | J396: 13 | K396: 6 | L396: 1 | M396: 57

Sheet Sheet4
A1: =Sheet2!G37 -> 地科院 平均值 | B1: =Sheet2!M37 -> 67.529412
A2: =Sheet2!G87 -> 法学院 平均值 | B2: =Sheet2!M87 -> 82.632653
A3: =Sheet2!G134 -> 公管院 平均值 | B3: =Sheet2!M134 -> 65.608696
A4: =Sheet2!G163 -> 化科院 平均值 | B4: =Sheet2!M163 -> 58.5
A5: =Sheet2!G218 -> 生科院 平均值 | B5: =Sheet2!M218 -> 81.833333
A6: =Sheet2!G245 -> 数科院 平均值 | B6: =Sheet2!M245 -> 48.423077
A7: =Sheet2!G286 -> 体科院 平均值 | B7: =Sheet2!M286 -> 74.25
A8: =Sheet2!G322 -> 外文院 平均值 | B8: =Sheet2!M322 -> 65.457143
A9: =Sheet2!G379 -> 文学院 平均值 | B9: =Sheet2!M379 -> 75.303571
A10: =Sheet2!G406 -> 物科院 平均值 | B10: =Sheet2!M406 -> 72.038462
A11: =Sheet2!G407 -> 总计平均值 | B11: =Sheet2!M407 -> 71.142132
