Workbook

Sheet Sheet1
A1: 计算机专业成绩
A2: 编号 | B2: 学号 | C2: 姓名 | D2: 性别 | E2: 出生日期 | F2: 籍贯 | G2: 院系 | H2: C语言 | I2: Word | J2: Excel | K2: PPT | L2: Access | M2: 成绩 | P2: 籍贯
A3: 001 | B3: 090010144 | C3: 褚梦佳 | D3: 女 | E3: 33288 | F3: 山东 | G3: 文学院 | H3: 14 | I3: 15 | J3: 10 | K3: 6 | L3: 9 | M3: =IF(COUNTIF(H3:L3,"=0")>=2,0,SUM(H3:L3)) -> 54 | P3: 河南 | Q3: =成绩>AVERAGE($M$3:$M$396) -> #NAME?
A4: 002 | B4: 090010145 | C4: 蔡敏梅 | D4: 女 | E4: 33280 | F4: 上海 | G4: 文学院 | H4: 11 | I4: 19 | J4: 19 | K4: 10 | L4: 9 | M4: =IF(COUNTIF(H4:L4,"=0")>=2,0,SUM(H4:L4)) -> 68 | P4: 山东 | Q4: =成绩>AVERAGE($M$3:$M$396) -> #NAME?
A5: 003 | B5: 090010146 | C5: 赵林莉 | D5: 女 | E5: 33574 | F5: 江苏 | G5: 文学院 | H5: 35 | I5: 20 | J5: 17 | K5: 7 | L5: 9 | M5: =IF(COUNTIF(H5:L5,"=0")>=2,0,SUM(H5:L5)) -> 88
A6: 004 | B6: 090010147 | C6: 糜义杰 | D6: 男 | E6: 33514 | F6: 江苏 | G6: 文学院 | H6: 29 | I6: 19 | J6: 19 | K6: 10 | L6: 9 | M6: =IF(COUNTIF(H6:L6,"=0")>=2,0,SUM(H6:L6)) -> 86
A7: 005 | B7: 090010148 | C7: 周丽萍 | D7: 女 | E7: 33314 | F7: 江苏 | G7: 文学院 | H7: 24 | I7: 18 | J7: 14 | K7: 7 | L7: 9 | M7: =IF(COUNTIF(H7:L7,"=0")>=2,0,SUM(H7:L7)) -> 72
A8: 006 | B8: 090010149 | C8: 王英 | D8: 女 | E8: 33430 | F8: 江苏 | G8: 文学院 | H8: 20 | I8: 20 | J8: 16 | K8: 10 | L8: 9 | M8: =IF(COUNTIF(H8:L8,"=0")>=2,0,SUM(H8:L8)) -> 75
A9: 007 | B9: 090010150 | C9: 陈子雅 | D9: 男 | E9: 33286 | F9: 江苏 | G9: 文学院 | H9: 22 | I9: 18 | J9: 16 | K9: 10 | L9: 9 | M9: =IF(COUNTIF(H9:L9,"=0")>=2,0,SUM(H9:L9)) -> 75 | P9: 编号 | Q9: 学号 | R9: 姓名 | S9: 性别 | T9: 出生日期 | U9: 籍贯 | V9: 院系 | W9: C语言 | X9: Word | Y9: Excel | Z9: PPT | AA9: Access | AB9: 成绩
A10: 008 | B10: 090010151 | C10: 周文洁 | D10: 女 | E10: 33317 | F10: 上海 | G10: 文学院 | H10: 28 | I10: 20 | J10: 12 | K10: 10 | L10: 9 | M10: =IF(COUNTIF(H10:L10,"=0")>=2,0,SUM(H10:L10)) -> 79 | P10: 020 | Q10: 090010107 | R10: 胡云 | S10: 女 | T10: 33382 | U10: 山东 | V10: 文学院 | W10: 29 | X10: 16 | Y10: 18 | Z10: 10 | AA10: 9 | AB10: 82
A11: 009 | B11: 090010152 | C11: 成立 | D11: 男 | E11: 33287 | F11: 江苏 | G11: 文学院 | H11: 26 | I11: 18 | J11: 18 | K11: 10 | L11: 9 | M11: =IF(COUNTIF(H11:L11,"=0")>=2,0,SUM(H11:L11)) -> 81 | P11: 029 | Q11: 090010116 | R11: 钱继英 | S11: 女 | T11: 33241 | U11: 山东 | V11: 文学院 | W11: 30 | X11: 19 | Y11: 19 | Z11: 8 | AA11: 9 | AB11: 85
A12: 010 | B12: 090010153 | C12: 陈晖 | D12: 男 | E12: 33283 | F12: 江苏 | G12: 文学院 | H12: 26 | I12: 20 | J12: 16 | K12: 9 | L12: 9 | M12: =IF(COUNTIF(H12:L12,"=0")>=2,0,SUM(H12:L12)) -> 80 | P12: 035 | Q12: 090010122 | R12: 韦道静 | S12: 女 | T12: 33514 | U12: 河南 | V12: 文学院 | W12: 34 | X12: 19 | Y12: 19 | Z12: 10 | AA12: 10 | AB12: 92
A13: 011 | B13: 090010154 | C13: 王玉芳 | D13: 女 | E13: 33431 | F13: 江苏 | G13: 文学院 | H13: 33 | I13: 20 | J13: 19 | K13: 10 | L13: 9 | M13: =IF(COUNTIF(H13:L13,"=0")>=2,0,SUM(H13:L13)) -> 91 | P13: 059 | Q13: 090020203 | R13: 齐海栓 | S13: 男 | T13: 33239 | U13: 河南 | V13: 外文院 | W13: 31 | X13: 18 | Y13: 19 | Z13: 10 | AA13: 9 | AB13: 87
A14: 012 | B14: 090010155 | C14: 邵艳 | D14: 女 | E14: 33251 | F14: 江苏 | G14: 文学院 | H14: 24 | I14: 20 | J14: 20 | K14: 10 | L14: 9 | M14: =IF(COUNTIF(H14:L14,"=0")>=2,0,SUM(H14:L14)) -> 83 | P14: 061 | Q14: 090020205 | R14: 顾继影 | S14: 男 | T14: 33365 | U14: 山东 | V14: 外文院 | W14: 27 | X14: 20 | Y14: 18 | Z14: 9 | AA14: 2 | AB14: 76
A15: 013 | B15: 090010156 | C15: 殷岳峰 | D15: 男 | E15: 33570 | F15: 山东 | G15: 文学院 | H15: 15 | I15: 15 | J15: 19 | K15: 7 | L15: 9 | M15: =IF(COUNTIF(H15:L15,"=0")>=2,0,SUM(H15:L15)) -> 65 | P15: 067 | Q15: 090020211 | R15: 周艳 | S15: 女 | T15: 33613 | U15: 河南 | V15: 外文院 | W15: 20 | X15: 17 | Y15: 18 | Z15: 8 | AA15: 9 | AB15: 72
A16: 014 | B16: 090010101 | C16: 董红 | D16: 女 | E16: 33349 | F16: 江苏 | G16: 文学院 | H16: 31 | I16: 9 | J16: 0 | K16: 4 | L16: 8 | M16: =IF(COUNTIF(H16:L16,"=0")>=2,0,SUM(H16:L16)) -> 52 | P16: 070 | Q16: 090020214 | R16: 孙中琦 | S16: 男 | T16: 33281 | U16: 河南 | V16: 外文院 | W16: 25 | X16: 18 | Y16: 15 | Z16: 10 | AA16: 5 | AB16: 73
A17: 015 | B17: 090010102 | C17: 王海霞 | D17: 女 | E17: 33402 | F17: 江苏 | G17: 文学院 | H17: 32 | I17: 20 | J17: 18 | K17: 10 | L17: 10 | M17: =IF(COUNTIF(H17:L17,"=0")>=2,0,SUM(H17:L17)) -> 90 | P17: 104 | Q17: 090030113 | R17: 陈奇志 | S17: 男 | T17: 33292 | U17: 河南 | V17: 数科院 | W17: 23 | X17: 15 | Y17: 19 | Z17: 6 | AA17: 9 | AB17: 72
A18: 016 | B18: 090010103 | C18: 闫静 | D18: 女 | E18: 33557 | F18: 江苏 | G18: 文学院 | H18: 33 | I18: 18 | J18: 10 | K18: 10 | L18: 10 | M18: =IF(COUNTIF(H18:L18,"=0")>=2,0,SUM(H18:L18)) -> 81 | P18: 124 | Q18: 090040107 | R18: 蔡秉滕 | S18: 男 | T18: 33278 | U18: 山东 | V18: 物科院 | W18: 22 | X18: 20 | Y18: 17 | Z18: 10 | AA18: 9 | AB18: 78
A19: 017 | B19: 090010104 | C19: 裴娟娟 | D19: 女 | E19: 33524 | F19: 江苏 | G19: 文学院 | H19: 31 | I19: 18 | J19: 19 | K19: 10 | L19: 7 | M19: =IF(COUNTIF(H19:L19,"=0")>=2,0,SUM(H19:L19)) -> 85 | P19: 138 | Q19: 090040121 | R19: 李洋 | S19: 男 | T19: 33436 | U19: 河南 | V19: 物科院 | W19: 34 | X19: 19 | Y19: 18 | Z19: 9 | AA19: 10 | AB19: 90
A20: 018 | B20: 090010105 | C20: 曹淤青 | D20: 男 | E20: 33286 | F20: 江苏 | G20: 文学院 | H20: 27 | I20: 18 | J20: 20 | K20: 10 | L20: 9 | M20: =IF(COUNTIF(H20:L20,"=0")>=2,0,SUM(H20:L20)) -> 84 | P20: 170 | Q20: 090050227 | R20: 张春丽 | S20: 女 | T20: 33548 | U20: 河南 | V20: 生科院 | W20: 35 | X20: 20 | Y20: 18 | Z20: 10 | AA20: 9 | AB20: 92
A21: 019 | B21: 090010106 | C21: 毛翠柳 | D21: 女 | E21: 33512 | F21: 北京 | G21: 文学院 | H21: 28 | I21: 20 | J21: 18 | K21: 10 | L21: 10 | M21: =IF(COUNTIF(H21:L21,"=0")>=2,0,SUM(H21:L21)) -> 86 | P21: 176 | Q21: 090050233 | R21: 韩玉鑫 | S21: 女 | T21: 33289 | U21: 山东 | V21: 生科院 | W21: 22 | X21: 20 | Y21: 19 | Z21: 10 | AA21: 9 | AB21: 80
... A33: 031 | B33: 090010118 | C33: 朱志香 | D33: 女 | E33: 33618 | F33: 江苏 | G33: 文学院 | H33: 31 | I33: 15 | J33: 20 | K33: 4 | L33: 6 | M33: =IF(COUNTIF(H33:L33,"=0")>=2,0,SUM(H33:L33)) -> 76 | P33: 385 | Q33: 090100731 | R33: 陈燕青 | S33: 女 | T33: 33284 | U33: 河南 | V33: 体科院 | W33: 32 | X33: 19 | Y33: 20 | Z33: 8 | AA33: 9 | AB33: 88
A34: 032 | B34: 090010119 | C34: 王亚丽 | D34: 女 | E34: 33516 | F34: 江苏 | G34: 文学院 | H34: 29 | I34: 19 | J34: 16 | K34: 6 | L34: 9 | M34: =IF(COUNTIF(H34:L34,"=0")>=2,0,SUM(H34:L34)) -> 79
A35: 033 | B35: 090010120 | C35: 刘晓芳 | D35: 女 | E35: 33383 | F35: 江苏 | G35: 文学院 | H35: 25 | I35: 18 | J35: 20 | K35: 9 | L35: 10 | M35: =IF(COUNTIF(H35:L35,"=0")>=2,0,SUM(H35:L35)) -> 82
A36: 034 | B36: 090010121 | C36: 王岩 | D36: 男 | E36: 33427 | F36: 江苏 | G36: 文学院 | H36: 33 | I36: 19 | J36: 15 | K36: 9 | L36: 9 | M36: =IF(COUNTIF(H36:L36,"=0")>=2,0,SUM(H36:L36)) -> 85
A37: 035 | B37: 090010122 | C37: 韦道静 | D37: 女 | E37: 33514 | F37: 河南 | G37: 文学院 | H37: 34 | I37: 19 | J37: 19 | K37: 10 | L37: 10 | M37: =IF(COUNTIF(H37:L37,"=0")>=2,0,SUM(H37:L37)) -> 92
A38: 036 | B38: 090010123 | C38: 孙芹 | D38: 女 | E38: 33274 | F38: 江苏 | G38: 文学院 | H38: 26 | I38: 17 | J38: 17 | K38: 7 | L38: 9 | M38: =IF(COUNTIF(H38:L38,"=0")>=2,0,SUM(H38:L38)) -> 76
A39: 037 | B39: 090010124 | C39: 缪茂桂 | D39: 女 | E39: 33516 | F39: 江苏 | G39: 文学院 | H39: 26 | I39: 19 | J39: 19 | K39: 7 | L39: 9 | M39: =IF(COUNTIF(H39:L39,"=0")>=2,0,SUM(H39:L39)) -> 80
A40: 038 | B40: 090010125 | C40: 钱丽萍 | D40: 女 | E40: 33243 | F40: 江苏 | G40: 文学院 | H40: 30 | I40: 17 | J40: 19 | K40: 4 | L40: 2 | M40: =IF(COUNTIF(H40:L40,"=0")>=2,0,SUM(H40:L40)) -> 72
A41: 039 | B41: 090010126 | C41: 陈洁 | D41: 女 | E41: 33285 | F41: 江苏 | G41: 文学院 | H41: 22 | I41: 15 | J41: 18 | K41: 7 | L41: 8 | M41: =IF(COUNTIF(H41:L41,"=0")>=2,0,SUM(H41:L41)) -> 70
A42: 040 | B42: 090010127 | C42: 李芳 | D42: 女 | E42: 33424 | F42: 北京 | G42: 文学院 | H42: 29 | I42: 18 | J42: 20 | K42: 8 | L42: 10 | M42: =IF(COUNTIF(H42:L42,"=0")>=2,0,SUM(H42:L42)) -> 85
A43: 041 | B43: 090010128 | C43: 王云 | D43: 女 | E43: 33433 | F43: 江苏 | G43: 文学院 | H43: 30 | I43: 19 | J43: 18 | K43: 9 | L43: 10 | M43: =IF(COUNTIF(H43:L43,"=0")>=2,0,SUM(H43:L43)) -> 86
A44: 042 | B44: 090010129 | C44: 金雨婷 | D44: 女 | E44: 33386 | F44: 江苏 | G44: 文学院 | H44: 31 | I44: 17 | J44: 18 | K44: 8 | L44: 9 | M44: =IF(COUNTIF(H44:L44,"=0")>=2,0,SUM(H44:L44)) -> 83
A45: 043 | B45: 090010130 | C45: 高建艮 | D45: 男 | E45: 33360 | F45: 山东 | G45: 文学院 | H45: 27 | I45: 17 | J45: 16 | K45: 3 | L45: 8 | M45: =IF(COUNTIF(H45:L45,"=0")>=2,0,SUM(H45:L45)) -> 71
... A396: 394 | B396: 090100740 | C396: 康婷婷 | D396: 女 | E396: 33416 | F396: 山东 | G396: 体科院 | H396: 19 | I396: 18 | J396: 13 | K396: 6 | L396: 1 | M396: =IF(COUNTIF(H396:L396,"=0")>=2,0,SUM(H396:L396)) -> 57

Sheet Sheet2
A1: 计算机专业成绩
A2: 编号 | B2: 学号 | C2: 姓名 | D2: 性别 | E2: 出生日期 | F2: 籍贯 | G2: 院系 | H2: C语言 | I2: Word | J2: Excel | K2: PPT | L2: Access | M2: 成绩
A3: 019 | B3: 090010106 | C3: 毛翠柳 | D3: 女 | E3: 33512 | F3: 北京 | G3: 文学院 | H3: 28 | I3: 20 | J3: 18 | K3: 10 | L3: 10 | M3: =IF(COUNTIF(H3:L3,"=0")>=2,0,SUM(H3:L3)) -> 86
A4: 040 | B4: 090010127 | C4: 李芳 | D4: 女 | E4: 33424 | F4: 北京 | G4: 文学院 | H4: 29 | I4: 18 | J4: 20 | K4: 8 | L4: 10 | M4: =IF(COUNTIF(H4:L4,"=0")>=2,0,SUM(H4:L4)) -> 85
A5: 068 | B5: 090020212 | C5: 杨月 | D5: 男 | E5: 33564 | F5: 北京 | G5: 外文院 | H5: 17 | I5: 19 | J5: 19 | K5: 9 | L5: 8 | M5: =IF(COUNTIF(H5:L5,"=0")>=2,0,SUM(H5:L5)) -> 72
A6: 080 | B6: 090020224 | C6: 李汤蕊 | D6: 女 | E6: 33432 | F6: 北京 | G6: 外文院 | H6: 32 | I6: 14 | J6: 8 | K6: 9 | L6: 1 | M6: =IF(COUNTIF(H6:L6,"=0")>=2,0,SUM(H6:L6)) -> 64
A7: 095 | B7: 090030104 | C7: 谢娇 | D7: 女 | E7: 33527 | F7: 北京 | G7: 数科院 | H7: 22 | I7: 0 | J7: 0 | K7: 1 | L7: 3 | M7: =IF(COUNTIF(H7:L7,"=0")>=2,0,SUM(H7:L7)) -> 0
A8: 107 | B8: 090030116 | C8: 宋海燕 | D8: 女 | E8: 33266 | F8: 北京 | G8: 数科院 | H8: 8 | I8: 0 | J8: 9 | K8: 0 | L8: 0 | M8: =IF(COUNTIF(H8:L8,"=0")>=2,0,SUM(H8:L8)) -> 0
A9: 119 | B9: 090040102 | C9: 龙发仁 | D9: 男 | E9: 33386 | F9: 北京 | G9: 物科院 | H9: 25 | I9: 17 | J9: 17 | K9: 10 | L9: 9 | M9: =IF(COUNTIF(H9:L9,"=0")>=2,0,SUM(H9:L9)) -> 78
A10: 133 | B10: 090040116 | C10: 曹苏明 | D10: 男 | E10: 33285 | F10: 北京 | G10: 物科院 | H10: 25 | I10: 17 | J10: 20 | K10: 10 | L10: 9 | M10: =IF(COUNTIF(H10:L10,"=0")>=2,0,SUM(H10:L10)) -> 81
A11: 173 | B11: 090050230 | C11: 刘芳 | D11: 女 | E11: 33493 | F11: 北京 | G11: 生科院 | H11: 35 | I11: 17 | J11: 18 | K11: 10 | L11: 9 | M11: =IF(COUNTIF(H11:L11,"=0")>=2,0,SUM(H11:L11)) -> 89
A12: 200 | B12: 090060303 | C12: 姜立英 | D12: 女 | E12: 33406 | F12: 北京 | G12: 地科院 | H12: 35 | I12: 15 | J12: 17 | K12: 10 | L12: 7 | M12: =IF(COUNTIF(H12:L12,"=0")>=2,0,SUM(H12:L12)) -> 84
A13: 218 | B13: 090060321 | C13: 郑宇洋 | D13: 男 | E13: 33304 | F13: 北京 | G13: 地科院 | H13: 29 | I13: 20 | J13: 18 | K13: 10 | L13: 8 | M13: =IF(COUNTIF(H13:L13,"=0")>=2,0,SUM(H13:L13)) -> 85
A14: 239 | B14: 090070408 | C14: 陈霓 | D14: 女 | E14: 33290 | F14: 北京 | G14: 化科院 | H14: 28 | I14: 18 | J14: 14 | K14: 9 | L14: 0 | M14: =IF(COUNTIF(H14:L14,"=0")>=2,0,SUM(H14:L14)) -> 69
... A19: 351 | B19: 090090643 | C19: 张晓霞 | D19: 女 | E19: 33564 | F19: 北京 | G19: 公管院 | H19: 12 | I19: 0 | J19: 0 | K19: 10 | L19: 7 | M19: =IF(COUNTIF(H19:L19,"=0")>=2,0,SUM(H19:L19)) -> 0
F20: 北京 平均值 | M20: =SUBTOTAL(1,M3:M19) -> 65.529412
A21: 035 | B21: 090010122 | C21: 韦道静 | D21: 女 | E21: 33514 | F21: 河南 | G21: 文学院 | H21: 34 | I21: 19 | J21: 19 | K21: 10 | L21: 10 | M21: =IF(COUNTIF(H21:L21,"=0")>=2,0,SUM(H21:L21)) -> 92
A22: 059 | B22: 090020203 | C22: 齐海栓 | D22: 男 | E22: 33239 | F22: 河南 | G22: 外文院 | H22: 31 | I22: 18 | J22: 19 | K22: 10 | L22: 9 | M22: =IF(COUNTIF(H22:L22,"=0")>=2,0,SUM(H22:L22)) -> 87
A23: 067 | B23: 090020211 | C23: 周艳 | D23: 女 | E23: 33613 | F23: 河南 | G23: 外文院 | H23: 20 | I23: 17 | J23: 18 | K23: 8 | L23: 9 | M23: =IF(COUNTIF(H23:L23,"=0")>=2,0,SUM(H23:L23)) -> 72
A24: 070 | B24: 090020214 | C24: 孙中琦 | D24: 男 | E24: 33281 | F24: 河南 | G24: 外文院 | H24: 25 | I24: 18 | J24: 15 | K24: 10 | L24: 5 | M24: =IF(COUNTIF(H24:L24,"=0")>=2,0,SUM(H24:L24)) -> 73
A25: 091 | B25: 090020235 | C25: 张刚柱 | D25: 男 | E25: 33551 | F25: 河南 | G25: 外文院 | H25: 28 | I25: 15 | J25: 17 | K25: 3 | L25: 1 | M25: =IF(COUNTIF(H25:L25,"=0")>=2,0,SUM(H25:L25)) -> 64
A26: 104 | B26: 090030113 | C26: 陈奇志 | D26: 男 | E26: 33292 | F26: 河南 | G26: 数科院 | H26: 23 | I26: 15 | J26: 19 | K26: 6 | L26: 9 | M26: =IF(COUNTIF(H26:L26,"=0")>=2,0,SUM(H26:L26)) -> 72
A27: 128 | B27: 090040111 | C27: 王秋实 | D27: 男 | E27: 33514 | F27: 河南 | G27: 物科院 | H27: 15 | I27: 11 | J27: 7 | K27: 0 | L27: 0 | M27: =IF(COUNTIF(H27:L27,"=0")>=2,0,SUM(H27:L27)) -> 0
A28: 138 | B28: 090040121 | C28: 李洋 | D28: 男 | E28: 33436 | F28: 河南 | G28: 物科院 | H28: 34 | I28: 19 | J28: 18 | K28: 9 | L28: 10 | M28: =IF(COUNTIF(H28:L28,"=0")>=2,0,SUM(H28:L28)) -> 90
A29: 155 | B29: 090050212 | C29: 徐志晔 | D29: 男 | E29: 33550 | F29: 河南 | G29: 生科院 | H29: 28 | I29: 19 | J29: 4 | K29: 0 | L29: 0 | M29: =IF(COUNTIF(H29:L29,"=0")>=2,0,SUM(H29:L29)) -> 0
A30: 170 | B30: 090050227 | C30: 张春丽 | D30: 女 | E30: 33548 | F30: 河南 | G30: 生科院 | H30: 35 | I30: 20 | J30: 18 | K30: 10 | L30: 9 | M30: =IF(COUNTIF(H30:L30,"=0")>=2,0,SUM(H30:L30)) -> 92
A31: 191 | B31: 090050248 | C31: 陈其 | D31: 女 | E31: 33291 | F31: 河南 | G31: 生科院 | H31: 30 | I31: 19 | J31: 18 | K31: 8 | L31: 9 | M31: =IF(COUNTIF(H31:L31,"=0")>=2,0,SUM(H31:L31)) -> 84
A32: 216 | B32: 090060319 | C32: 李钢 | D32: 男 | E32: 33383 | F32: 河南 | G32: 地科院 | H32: 15 | I32: 12 | J32: 0 | K32: 0 | L32: 0 | M32: =IF(COUNTIF(H32:L32,"=0")>=2,0,SUM(H32:L32)) -> 0
... A38: 385 | B38: 090100731 | C38: 陈燕青 | D38: 女 | E38: 33284 | F38: 河南 | G38: 体科院 | H38: 32 | I38: 19 | J38: 20 | K38: 8 | L38: 9 | M38: =IF(COUNTIF(H38:L38,"=0")>=2,0,SUM(H38:L38)) -> 88
F39: 河南 平均值 | M39: =SUBTOTAL(1,M21:M38) -> 64.944444
A40: 003 | B40: 090010146 | C40: 赵林莉 | D40: 女 | E40: 33574 | F40: 江苏 | G40: 文学院 | H40: 35 | I40: 20 | J40: 17 | K40: 7 | L40: 9 | M40: =IF(COUNTIF(H40:L40,"=0")>=2,0,SUM(H40:L40)) -> 88
A41: 004 | B41: 090010147 | C41: 糜义杰 | D41: 男 | E41: 33514 | F41: 江苏 | G41: 文学院 | H41: 29 | I41: 19 | J41: 19 | K41: 10 | L41: 9 | M41: =IF(COUNTIF(H41:L41,"=0")>=2,0,SUM(H41:L41)) -> 86
A42: 005 | B42: 090010148 | C42: 周丽萍 | D42: 女 | E42: 33314 | F42: 江苏 | G42: 文学院 | H42: 24 | I42: 18 | J42: 14 | K42: 7 | L42: 9 | M42: =IF(COUNTIF(H42:L42,"=0")>=2,0,SUM(H42:L42)) -> 72
A43: 006 | B43: 090010149 | C43: 王英 | D43: 女 | E43: 33430 | F43: 江苏 | G43: 文学院 | H43: 20 | I43: 20 | J43: 16 | K43: 10 | L43: 9 | M43: =IF(COUNTIF(H43:L43,"=0")>=2,0,SUM(H43:L43)) -> 75
A44: 007 | B44: 090010150 | C44: 陈子雅 | D44: 男 | E44: 33286 | F44: 江苏 | G44: 文学院 | H44: 22 | I44: 18 | J44: 16 | K44: 10 | L44: 9 | M44: =IF(COUNTIF(H44:L44,"=0")>=2,0,SUM(H44:L44)) -> 75
A45: 009 | B45: 090010152 | C45: 成立 | D45: 男 | E45: 33287 | F45: 江苏 | G45: 文学院 | H45: 26 | I45: 18 | J45: 18 | K45: 10 | L45: 9 | M45: =IF(COUNTIF(H45:L45,"=0")>=2,0,SUM(H45:L45)) -> 81
A46: 010 | B46: 090010153 | C46: 陈晖 | D46: 男 | E46: 33283 | F46: 江苏 | G46: 文学院 | H46: 26 | I46: 20 | J46: 16 | K46: 9 | L46: 9 | M46: =IF(COUNTIF(H46:L46,"=0")>=2,0,SUM(H46:L46)) -> 80
A47: 011 | B47: 090010154 | C47: 王玉芳 | D47: 女 | E47: 33431 | F47: 江苏 | G47: 文学院 | H47: 33 | I47: 20 | J47: 19 | K47: 10 | L47: 9 | M47: =IF(COUNTIF(H47:L47,"=0")>=2,0,SUM(H47:L47)) -> 91
A48: 012 | B48: 090010155 | C48: 邵艳 | D48: 女 | E48: 33251 | F48: 江苏 | G48: 文学院 | H48: 24 | I48: 20 | J48: 20 | K48: 10 | L48: 9 | M48: =IF(COUNTIF(H48:L48,"=0")>=2,0,SUM(H48:L48)) -> 83
A49: 014 | B49: 090010101 | C49: 董红 | D49: 女 | E49: 33349 | F49: 江苏 | G49: 文学院 | H49: 31 | I49: 9 | J49: 0 | K49: 4 | L49: 8 | M49: =IF(COUNTIF(H49:L49,"=0")>=2,0,SUM(H49:L49)) -> 52
...

Sheet Sheet3
A1: =Sheet2!F20 -> 北京 平均值 | B1: =Sheet2!M20 -> 65.529412
A2: =Sheet2!F39 -> 河南 平均值 | B2: =Sheet2!M39 -> 64.944444
A3: =Sheet2!F360 -> 江苏 平均值 | B3: =Sheet2!M360 -> 72.23125
A4: =Sheet2!F389 -> 山东 平均值 | B4: =Sheet2!M389 -> 63.857143
A5: =Sheet2!F401 -> 上海 平均值 | B5: =Sheet2!M401 -> 76.818182
A6: =Sheet2!F402 -> 总计平均值 | B6: =Sheet2!M402 -> 71.142132
